Workbook

Sheet SCNs
A1: Area | B1: Scene | C1: Who | D1: Shown when | E1: Japanese | F1: JP_Len | G1: English | H1: EN_Len | I1: Comments | J1: Filename | K1: Offset
B2: 00IPL #1 | E2: はるか昔 | F2: =LEN(E2) | G2: Long ago... | H2: =LEN(G2) | J2: 00IPL.SCN | K2: 0x00082
B3: 00IPL #1 | E3: その漆黒の竜は多くの国を焼きつくし | F3: =LEN(E3) | G3: The infernal black dragon arose to incinerate many kingdoms. | H3: =LEN(G3) | J3: 00IPL.SCN | K3: 0x000c3
B4: 00IPL #1 | E4: 幾千もの人の肉を喰らった | F4: =LEN(E4) | G4: The beast feasted on the flesh of countless thousands. | H4: =LEN(G4) | J4: 00IPL.SCN | K4: 0x00111
B5: 00IPL #2 | E5: 比類なき腕を誇った勇者の剣も | F5: =LEN(E5) | G5: The legendary blade wielded by a powerful warrior... | H5: =LEN(G5) | J5: 00IPL.SCN | K5: 0x0018f
B6: 00IPL #2 | E6: 偉大なる魔導師の天地を揺るがす魔法も | F6: =LEN(E6) | G6: Magic that could tear heaven asunder cast by a powerful mage... | H6: =LEN(G6) | J6: 00IPL.SCN | K6: 0x001de
B7: 00IPL #2 | E7: 聖なる神の力を具現する高僧の祈りも | F7: =LEN(E7) | G7: The holiest prayers of a high priest imbued by God... | H7: =LEN(G7) | J7: 00IPL.SCN | K7: 0x00231
B8: 00IPL #2 | E8: 彼の者には通用せず | F8: =LEN(E8) | G8: None were effective. | H8: =LEN(G8) | J8: 00IPL.SCN | K8: 0x00283
B9: 00IPL #2 | E9: 追い詰められた人々は、ついに魔を以て、これを打ち倒さんとした | F9: =LEN(E9) | G9: Finally those tormented by the beast turned to demonic powers to defeat the dragon. | H9: =LEN(G9) | J9: 00IPL.SCN | K9: 0x002cd
B10: 00IPL #3 | E10: 滅ぼせぬもの無き武器を | F10: =LEN(E10) | G10: Weapons with truly unstoppable power... | H10: =LEN(G10) | J10: 00IPL.SCN | K10: 0x0035e
B11: 00IPL #3 | E11: この世のものにあらざる武器を | F11: =LEN(E11) | G11: Weapons not of this world. | H11: =LEN(G11) | J11: 00IPL.SCN | K11: 0x003aa
B12: 00IPL #4 | E12: ・・・そして | F12: =LEN(E12) | G12: Until... | H12: =LEN(G12) | J12: 00IPL.SCN | K12: 0x0042b
B13: 00IPL #4 | E13: 一振の剣が造られたのである | F13: =LEN(E13) | G13: ...one single sword was forged. | H13: =LEN(G13) | I13: After this the title shows the name of the sword. | J13: 00IPL.SCN | K13: 0x00472
B14: 00IPL #5 | F14: =LEN(E14) | G14: [BLANK] | H14: =LEN(G14) | J14: 00IPL.SCN | K14: 0x00551
B15: 00IPL #5 | E15: ・・・これは | F15: =LEN(E15) | G15: Is this... | H15: =LEN(G15) | J15: 00IPL.SCN | K15: 0x0056e
B16: 00IPL #5 | F16: =LEN(E16) | G16: [BLANK] | H16: =LEN(G16) | J16: 00IPL.SCN | K16: 0x00582
B17: 00IPL #5 | E17: ・・・おれの乗っていた船か？ | F17: =LEN(E17) | G17: ...is it the ship I was traveling on? | H17: =LEN(G17) | J17: 00IPL.SCN | K17: 0x00597
B18: 00IPL #5 | F18: =LEN(E18) | G18: [BLANK] | H18: =LEN(G18) | J18: 00IPL.SCN | K18: 0x005c2
B19: 00IPL #5 | E19: 静かで、雨の一滴も降らぬ嵐でした。 | F19: =LEN(E19) | G19: That quiet storm, with not a drop of rain... | H19: =LEN(G19) | J19: 00IPL.SCN | K19: 0x005d4
B20: 00IPL #5 | F20: =LEN(E20) | G20: [BLANK] | H20: =LEN(G20) | J20: 00IPL.SCN | K20: 0x005fe
B21: 00IPL #5 | E21: 凡庸な感想ですが、 | F21: =LEN(E21) | G21: Any explanation is inadequate, but... | H21: =LEN(G21) | J21: 00IPL.SCN | K21: 0x00618
B22: 00IPL #5 | F22: =LEN(E22) | G22: [BLANK] | H22: =LEN(G22) | J22: 00IPL.SCN | K22: 0x00632
B23: 00IPL #5 | E23: 奇妙な・・・としか言い様がありません。 | F23: =LEN(E23) | G23: it was truly bizarre... no words can describe it. | H23: =LEN(G23) | J23: 00IPL.SCN | K23: 0x00642
B24: 00IPL #5 | F24: =LEN(E24) | G24: [BLANK] | H24: =LEN(G24) | J24: 00IPL.SCN | K24: 0x00670
B25: 00IPL #5 | E25: あのような嵐は、土地の古老でさえ、 | F25: =LEN(E25) | G25: It was the first time that anyone, | H25: =LEN(G25) | J25: 00IPL.SCN | K25: 0x00682
B26: 00IPL #5 | F26: =LEN(E26) | G26: [BLANK] | H26: =LEN(G26) | J26: 00IPL.SCN | K26: 0x006ac
B27: 00IPL #5 | E27: 目にするのは初めてだったことでしょう。 | F27: =LEN(E27) | G27: even the elders of the land, had seen such a storm. | H27: =LEN(G27) | J27: 00IPL.SCN | K27: 0x006bc
B28: 00IPL #5 | F28: =LEN(E28) | G28: [BLANK] | H28: =LEN(G28) | J28: 00IPL.SCN | K28: 0x006f1
B29: 00IPL #5 | E29: 手荒い歓迎だったな。 | F29: =LEN(E29) | G29: It was a violent welcome. | H29: =LEN(G29) | J29: 00IPL.SCN | K29: 0x0070a
B30: 00IPL #5 | F30: =LEN(E30) | G30: [BLANK] | H30: =LEN(G30) | J30: 00IPL.SCN | K30: 0x00726
B31: 00IPL #5 | E31: どうやら、おれはこの国に嫌われてるらしい | F31: =LEN(E31) | G31: It would seem this country already despises me... | H31: =LEN(G31) | J31: 00IPL.SCN | K31: 0x00735
B32: 00IPL #5 | F32: =LEN(E32) | G32: [BLANK] | H32: =LEN(G32) | J32: 00IPL.SCN | K32: 0x0076c
B33: 00IPL #5 | E33: あなたはなぜ、ここクライツェンに？ | F33: =LEN(E33) | G33: "What are you doing here in Kreitzen?" | H33: =LEN(G33) | J33: 00IPL.SCN | K33: 0x0077e
B34: 00IPL #5 | F34: =LEN(E34) | G34: [BLANK] | H34: =LEN(G34) | J34: 00IPL.SCN | K34: 0x007af
B35: 00IPL #5 | E35: 剣の修行の旅をしている。 | F35: =LEN(E35) | G35: "I'm journeying to improve my sword skills, | H35: =LEN(G35) | J35: 00IPL.SCN | K35: 0x007c6
B36: 00IPL #5 | F36: =LEN(E36) | G36: [BLANK] | H36: =LEN(G36) | J36: 00IPL.SCN | K36: 0x007e6
B37: 00IPL #5 | E37: 別にここでなくても、かまわなかったんだが・・・ | F37: =LEN(E37) | G37: I just ended up in Kreitzen, any place would have been fine." | H37: =LEN(G37) | J37: 00IPL.SCN | K37: 0x007f2
B38: 00IPL #5 | F38: =LEN(E38) | G38: [BLANK] | H38: =LEN(G38) | J38: 00IPL.SCN | K38: 0x0082f
B39: 00IPL #5 | E39: 剣を極めた後、あなたは何を成すつもりか？ | F39: =LEN(E39) | G39: "And what will you do once you've mastered the blade?" | H39: =LEN(G39) | J39: 00IPL.SCN | K39: 0x0083e
B40: 00IPL #5 | F40: =LEN(E40) | G40: [BLANK] | H40: =LEN(G40) | J40: 00IPL.SCN | K40: 0x00875
...

Sheet BSDs
A1: Filename | B1: Offset | C1: Japanese | D1: JP_len | E1: English | F1: EN_len | G1: Comments
A2: C020_X10.BSD | B2: 0x00218 | C2: シノブ | D2: 29 | E2: Shinobu | F2: 0
A3: C020_X10.BSD | B3: 0x0023a | C3: 「逃げられない？！」 | D3: 22 | F3: 0
A4: C020_X10.BSD | B4: 0x00283 | C4: カイエス | D4: 28 | E4: Keiuss | F4: 0
A5: C020_X10.BSD | B5: 0x002a5 | C5: 「逃げられんようだな・・・」 | D5: 18 | F5: 0
A6: C021_X10.BSD | B6: 0x0028a | C6: シノブ | D6: 29 | E6: Shinobu | F6: 0
A7: C021_X10.BSD | B7: 0x002ac | C7: 「逃げられない？！」 | D7: 22 | F7: 0
A8: C021_X10.BSD | B8: 0x002f5 | C8: カイエス | D8: 28 | E8: Keiuss | F8: 0
A9: C021_X10.BSD | B9: 0x00317 | C9: 「逃げられんようだな・・・」 | D9: 18 | F9: 0
A10: C021_X10.BSD | B10: 0x00460 | C10: ゼフュードル | D10: 6 | E10: Zerfuedel | F10: 0
A11: C021_X10.BSD | B11: 0x0046e | C11: 「意外と、やるじゃねえか？ | D11: 13 | F11: 0
A12: C021_X10.BSD | B12: 0x0048a | C12: だがよ、そんなナマクラな剣で、 | D12: 16 | F12: 0
A13: C021_X10.BSD | B13: 0x004ac | C13: おれに立ち向かったのが間違いだ | D13: 16 | F13: 0
A14: C021_X10.BSD | B14: 0x004ce | C14: ったな？ この《征嵐剣》の力を | D14: 16 | F14: 0
A15: C021_X10.BSD | B15: 0x004f0 | C15: 見せてやるぜ！」 | D15: 9 | F15: 0
A16: C021_X10.BSD | B16: 0x006ae | C16: ゼフュードル | D16: 6 | E16: Zerfuedel | F16: 0
A17: C021_X10.BSD | B17: 0x006bc | C17: 「一昨日きやがれ！！」 | D17: 11 | F17: 0
A18: C021_X10.BSD | B18: 0x006fb | C18: ゼフュードル | D18: 6 | E18: Zerfuedel | F18: 0
A19: C021_X10.BSD | B19: 0x00709 | C19: 「へっ、《餓嵐》の味はどうだ？」 | D19: 16 | F19: 0
A20: C021_X10.BSD | B20: 0x00752 | C20: カイエス | D20: 4 | E20: Keiuss | F20: 0
A21: C021_X10.BSD | B21: 0x0075c | C21: 「その技・・・ | D21: 7 | F21: 0
A22: C021_X10.BSD | B22: 0x0076c | C22: 自ら編み出したのか？」 | D22: 12 | F22: 0
A23: C021_X10.BSD | B23: 0x007ad | C23: ゼフュードル | D23: 6 | E23: Zerfuedel | F23: 0
A24: C021_X10.BSD | B24: 0x007bb | C24: 「まあ、な。 | D24: 6 | F24: 0
A25: C021_X10.BSD | B25: 0x007c9 | C25: ただ、あんまり無茶な技なんで、 | D25: 16 | F25: 0
A26: C021_X10.BSD | B26: 0x007eb | C26: この《征嵐剣》以外の剣じゃ、で | D26: 16 | F26: 0
A27: C021_X10.BSD | B27: 0x0080d | C27: きねぇがよ。」 | D27: 8 | F27: 0
A28: C021_X10.BSD | B28: 0x00846 | C28: カイエス | D28: 4 | E28: Keiuss | F28: 0
A29: C021_X10.BSD | B29: 0x00850 | C29: 「・・・さすがだ」 | D29: 9 | F29: 0
A30: C021_X10.BSD | B30: 0x0088b | C30: ゼフュードル | D30: 6 | E30: Zerfuedel | F30: 0
A31: C021_X10.BSD | B31: 0x00899 | C31: 「ま、おれは天才だからな」 | D31: 13 | F31: 0
A32: C021_X10.BSD | B32: 0x008dc | C32: カイエス | D32: 4 | E32: Keiuss | F32: 0
A33: C021_X10.BSD | B33: 0x008e6 | C33: 「師匠も、お前の天賦の才は認めて | D33: 16 | F33: 0
A34: C021_X10.BSD | B34: 0x00908 | C34: いた・・・」 | D34: 7 | F34: 0
A35: C021_X10.BSD | B35: 0x0093f | C35: ゼフュードル | D35: 6 | E35: Zerfuedel | F35: 0
A36: C021_X10.BSD | B36: 0x0094d | C36: 「そのくせに、奥義はてめぇに譲ろ | D36: 16 | F36: 0
A37: C021_X10.BSD | B37: 0x0096f | C37: うってんだからなぁ。 | D37: 11 | F37: 0
A38: C021_X10.BSD | B38: 0x00987 | C38: あのもうろくじじいが・・・ | D38: 14 | F38: 0
A39: C021_X10.BSD | B39: 0x009a5 | C39: ・・・ま、残念だったな、おい？ | D39: 16 | F39: 0
A40: C021_X10.BSD | B40: 0x009c7 | C40: てめえの負けだ」 | D40: 9 | F40: 0
...

Sheet BD.BIN
A1: Offset | B1: Japanese | C1: JP_len | D1: English | E1: EN_len | F1: Comments
A2: 0x09e01 | B2: カイエスは | C2: =LEN(B2) | D2: Keiuss gained | E2: =LEN(D1) | F2: Caius got | G2: Is this used for other things besides "got" situations? Such as "Keiuss fell asleep" or "Keiuss has fallen"? | H2: Pretty sure it's just post-battle item/exp/gold/level stuff, but I will check.
A3: 0x09e33 | B3: シノブは | C3: =LEN(B3) | D3: Shinobu gained | E3: =LEN(F2) | F3: Shinobu got | G3: Same as above
A4: 0x09e3d | B4: ptsの経験値を得た。 | C4: =LEN(B4) | D4: EXP. | E4: =LEN(F4) | F4: experience pts.
A5: 0x09e51 | B5: レベルアップした。 | C5: =LEN(B5) | D5: a level! | E5: =LEN(F5) | F5: levelled up.
A6: 0x09ed2 | B6: \f | C6: =LEN(B6) | D6: \f | E6: =LEN(F6) | F6: Gold.
A7: 0x09ed5 | B7: Goldを得た。 | D7: gold taken. | E7: =LEN(F7)
A8: 0x09f2c | B8: を手に入れた。 | C8: =LEN(B8) | D8: received. | E8: =LEN(F8) | F8: .
A9: 0x09f6b | B9: パーティは全滅した。 | C9: =LEN(B9) | D9: Annihilated... | E9: =LEN(F9) | F9: Annihilated... | G9: Too long?
A10: 0x0b1e0 | B10: カイエス | C10: =LEN(B10) | D10: Keiuss | E10: =LEN(F10) | F10: Caius
A11: 0x0b1e9 | B11: シノブ | C11: =LEN(B11) | D11: Shinobu | E11: =LEN(F11) | F11: Shinobu
A12: 0x0b1f0 | B12: シノブ | C12: =LEN(B12) | D12: Shinobu | E12: =LEN(F12) | F12: Shinobu
A13: 0x0ba4a | B13: ステータス | C13: =LEN(B13) | D13: Status | E13: =LEN(F13) | F13: Status
A14: 0x0ba55 | B14: 魔法 | C14: =LEN(B14) | D14: Magic | E14: =LEN(F14) | F14: Magic
A15: 0x0ba5a | B15: 道具 | C15: =LEN(B15) | D15: Item | E15: =LEN(F15) | F15: Item
A16: 0x0ba5f | B16: 装備 | C16: =LEN(B16) | D16: Equipment | E16: =LEN(F16) | F16: Equipment
A17: 0x0ba64 | B17: システム | C17: =LEN(B17) | D17: System | E17: =LEN(F17) | F17: System
A18: 0x0ba6e | B18: ステータス | C18: =LEN(B18) | D18: Status | E18: =LEN(F18) | F18: Status
A19: 0x0ba79 | B19: 道具 | C19: =LEN(B19) | D19: Item | E19: =LEN(F19) | F19: Item
A20: 0x0ba7e | B20: 装備 | C20: =LEN(B20) | D20: Equipment | E20: =LEN(F20) | F20: Equipment
A21: 0x0ba83 | B21: システム | C21: =LEN(B21) | D21: System | E21: =LEN(F21) | F21: System
... A40: 0x0bb16 | B40: 剣士 | C40: =LEN(B40) | D40: Swordsman | E40: =LEN(F40) | F40: Swordsman
A41: 0x0bb1c | B41: 術法士 | C41: =LEN(B41) | D41: Mystic Knight | E41: =LEN(F41) | F41: Artist | G41: This is tougher, means someone with a lot of special techniques for fighting, but implies they're also a knight of a sort.
A42: 0x0bb2d | B42: カイエス・ナインターク | C42: =LEN(B42) | D42: Keiuss Neintauk | E42: =LEN(F42) | F42: Caius Ninthaku
A43: 0x0bb44 | B43: シノブ・リュード | C43: =LEN(B43) | D43: Shinobu Ryudo | E43: =LEN(F43) | F43: Shinobu Ryudo
A44: 0x0bb58 | B44: 正常 | C44: =LEN(B44) | D44: Normal | E44: =LEN(F44) | F44: Normal | G44: Status (As opposed to like poisoned or something)
A45: 0x0bb5d | B45: 攻撃力 | C45: =LEN(B45) | D45: Attack | E45: =LEN(F45) | F45: Attack
A46: 0x0bb64 | B46: 防御力 | C46: =LEN(B46) | D46: Defense | E46: =LEN(F46) | F46: Defense
A47: 0x0bb6b | B47: 魔法攻撃力 | C47: =LEN(B47) | D47: Mg. Attack | E47: =LEN(F47) | F47: Ma. Attack
A48: 0x0bb76 | B48: 魔法防御力 | C48: =LEN(B48) | D48: Mg. Defense | E48: =LEN(F48) | F48: Ma. Defense
A49: 0x0bb81 | B49: 命中力 | C49: =LEN(B49) | D49: Accuracy | E49: =LEN(F49) | F49: Accuracy
A50: 0x0bb88 | B50: 回避力 | C50: =LEN(B50) | D50: Evasion | E50: =LEN(F50) | F50: Evasion
A51: 0x0bb8f | B51: 素早さ | C51: =LEN(B51) | D51: Speed | E51: =LEN(F51) | F51: Speed
A52: 0x0bb96 | B52: 武器 | C52: =LEN(B52) | D52: Weapon | E52: =LEN(F52) | F52: Weapon
A53: 0x0bb9b | B53: 防具 | C53: =LEN(B53) | D53: Armor | E53: =LEN(F53) | F53: Armor
A54: 0x0bba0 | B54: ｱｲﾃﾑ 1 | C54: =LEN(B54) | D54: Acc. 1 | E54: =LEN(F54) | F54: Item 1
A55: 0x0bbac | B55: ｱｲﾃﾑ 2 | C55: =LEN(B55) | D55: Acc. 2 | E55: =LEN(F55) | F55: Item 2
A56: 0x0bbbe | B56: 【 剣技 】 | C56: =LEN(B56) | D56: [Sword Techs] | E56: =LEN(F56) | F56: [Sword Techs]
... A94: 0x0e78a | B94: ＬＣＤ８階調 | C94: =LEN(B94) | D94: 8-shade LCD | E94: =LEN(F94) | F94: LCD 8

Sheet ITEM.SMI
A1: Offset | B1: Japanese | C1: JP_len | D1: English | E1: EN_len | F1: Description | G1: Comments
A2: 0x02bfc | B2: Ｄｕｍｍｙ | C2: =LEN(B2) | E2: =LEN(D2) | F2: Ｎｏｎｅ
A3: 0x02c07 | B3: 薬草 | C3: =LEN(B3) | D3: Herbs | E3: =LEN(D3) | F3: ＨＰを２００Ｐ回復する
A4: 0x02c0c | B4: ポーション | C4: =LEN(B4) | D4: Potion | E4: =LEN(D4) | F4: ＨＰを５００Ｐ回復する
A5: 0x02c17 | B5: ハイポーション | C5: =LEN(B5) | D5: High Potion | E5: =LEN(D5) | F5: ＨＰを１０００Ｐ回復する | H5: High Potion | I5: Strong Potion | J5: Mega Potion
A6: 0x02c26 | B6: エリクサー | C6: =LEN(B6) | D6: Elixir | E6: =LEN(D6) | F6: ＨＰ・ＭＰを完全回復する
A7: 0x02c31 | B7: 風船草 | C7: =LEN(B7) | E7: =LEN(D7) | F7: 眠りから覚ます | H7: Balloon Grass | J7: Balloon Weed | K7: Balloon Weed | L7: Wake-Up Weed
A8: 0x02c38 | B8: 毒消し | C8: =LEN(B8) | D8: Antidote | E8: =LEN(D8) | F8: 解毒薬
A9: 0x02c3f | B9: テンダーオイル | C9: =LEN(B9) | D9: Tender Oil | E9: =LEN(D9) | F9: 麻痺の治療をする | G9: Cures Paralysis
A10: 0x02c4e | B10: ムーンハーブ | C10: =LEN(B10) | D10: Lunar Herb | E10: =LEN(D10) | F10: 眠り・毒・麻痺および、魔法の影響を打ち消す
A11: 0x02c5b | B11: 気付け薬 | C11: =LEN(B11) | D11: Smelling Salts | E11: =LEN(D11) | F11: 気絶を治療し ＨＰをある程度回復する
A12: 0x02c64 | B12: 崩呪香 | C12: =LEN(B12) | D12: Purifying Incense | E12: =LEN(D12) | F12: 禁止状態の解除をする香木
A13: 0x02c6b | B13: エーテル | C13: =LEN(B13) | D13: Ether | E13: =LEN(D13) | F13: ＭＰ３００Ｐ回復する
A14: 0x02c74 | B14: エーテルプラス | C14: =LEN(B14) | D14: Ether Plus | E14: =LEN(D14) | F14: ＭＰ１０００Ｐ回復する | H14: Ether Plus | I14: Strong Ether | J14: Mega Ether
A15: 0x02c83 | B15: 沈黙の巻物 | C15: =LEN(B15) | D15: Silencing Scroll | E15: =LEN(D15) | F15: 敵の魔法・技を禁止する力を秘める巻物
A16: 0x02c8e | B16: 守護の巻物 | C16: =LEN(B16) | E16: =LEN(D16) | F16: 敵の物理攻撃を防ぐ力を秘める巻物 | H16: Protection Scroll | I16: Guardian Scroll
A17: 0x02c99 | B17: 月光の粉 | C17: =LEN(B17) | E17: =LEN(D17) | F17: 魔力付与の力を秘める不思議な粉末 | H17: Moonlight Dust | I17: Moonlight Powder
A18: 0x02ca2 | B18: 赤の呪石 | C18: =LEN(B18) | E18: =LEN(D18) | F18: 火の呪力が封じられた石 | H18: Red Curse Stone (Literal)
A19: 0x02cab | B19: 青の呪石 | C19: =LEN(B19) | E19: =LEN(D19) | F19: 氷の呪力が封じられた石 | H19: Blue...
A20: 0x02cb4 | B20: 黄の呪石 | C20: =LEN(B20) | E20: =LEN(D20) | F20: 雷の呪力が封じられた石 | H20: Yellow...
A21: 0x02cbd | B21: 火龍の牙 | C21: =LEN(B21) | E21: =LEN(D21) | F21: 火龍を呼ぶ力を持つ宝石 | H21: Fire Dragon Flame | I21: Flame Dragon Fang | J21: Firewyrm Fang | K21: Flame Drake Fang
A22: 0x02cc6 | B22: 小さな靴 | C22: =LEN(B22) | E22: =LEN(D22) | F22: 巨神を呼ぶ力を持つ魔法の品 | H22: Small Shoes | I22: Giant's Tiny Shoes | J22: Tiny Shoes
A23: 0x02ccf | B23: 天使の矢 | C23: =LEN(B23) | D23: Angel's Arrow | E23: =LEN(D23) | F23: 戦の女神を呼ぶ力を持つ矢
A24: 0x02cd8 | B24: 銀の鈴 | C24: =LEN(B24) | D24: Silver Bell | E24: =LEN(D24) | F24: 敵の攻撃無効化能力を封じる
A25: 0x02cdf | B25: 金の鈴 | C25: =LEN(B25) | D25: Golden Bell | E25: =LEN(D25) | F25: ?
A26: 0x02ce6 | B26: 至福の鈴 | C26: =LEN(B26) | D26: Blissful Bell | E26: =LEN(D26) | F26: ?
A27: 0x02cef | B27: ロングソード | C27: =LEN(B27) | D27: Longsword | E27: =LEN(D27) | F27: 広く普及している 一般的な長剣
A28: 0x02cfc | B28: ブロードソード | C28: =LEN(B28) | D28: Broadsword | E28: =LEN(D28) | F28: 攻撃力は長剣に勝るが 命中率が低い大剣
A29: 0x02d0b | B29: シルバーブレード | C29: =LEN(B29) | D29: Silver Blade | E29: =LEN(D29) | F29: 魔力を秘めた銀で作られた剣
A30: 0x02d1c | B30: 石の王 | C30: =LEN(B30) | D30: Kingstone Blade | E30: =LEN(D30) | F30: 鉱石で作られたの石の剣 | G30: May be an actual stone? Has a high counter rate
A31: 0x02d23 | B31: 逆鱗の剣 | C31: =LEN(B31) | D31: Scale Blade | E31: =LEN(D31) | F31: 竜の逆鱗を剥がして作った剣 怒りのパワーを秘める
A32: 0x02d2c | B32: エグゼキューショナーズ | C32: =LEN(B32) | D32: Executioner | E32: =LEN(D32) | F32: 《屠殺人》の名を持つ剣。強大な攻撃力を誇るが？
A33: 0x02d43 | B33: クリムゾンマスター | C33: =LEN(B33) | D33: Crimson Master | E33: =LEN(D33) | F33: 《深紅の支配者》の名を持つ、炎の魔剣 | G33: Does fire damage
A34: 0x02d56 | B34: ダモクレスソード | C34: =LEN(B34) | D34: Sword of Damocles | E34: =LEN(D34) | F34: 比類ない切れ味を誇り、所有者の各能力を上昇させる秘剣だが？
A35: 0x02d67 | B35: 覇者の剣 | C35: =LEN(B35) | D35: Champion's Sword | E35: =LEN(D35) | F35: 一般に普及した剣では最強の逸品
A36: 0x02d70 | B36: 獅心剣 | C36: =LEN(B36) | D36: Samurai Sword | E36: =LEN(D36) | F36: いにしえの時 黒竜と戦った勇者が携えていた伝説の剣
A37: 0x02d77 | B37: ブレードスターライト | C37: =LEN(B37) | D37: Starlight Blade | E37: =LEN(D37) | F37: 《星の光》の名を持つ神速の魔剣
A38: 0x02d8c | B38: ドーンパープル | C38: =LEN(B38) | D38: Dawn Purple | E38: =LEN(D38) | F38: 《暁の紫》の名を持つ、必中の魔剣 | G38: Appears to be an item, not a weapon
A39: 0x02d9b | B39: 騎士の剣 | C39: =LEN(B39) | D39: Knight's Sword | E39: =LEN(D39) | F39: 騎士のために作られた大剣
A40: 0x02da4 | B40: はやぶさの剣 | C40: =LEN(B40) | D40: Falcon Blade | E40: =LEN(D40) | F40: 攻撃回数を増加させる魔剣 | H40: Hayabusa Sword | I40: Falcon Blade | J40: (Note: Does anybody know the story of Hayabusa???)
...

Sheet KIES.SMI
A1: Offset | B1: Japanese | C1: JP_len | D1: English | E1: EN_len | F1: Comments
A2: 0x00de1 | B2: 三日月 | C2: =LEN(B2) | E2: =LEN(D2)
A3: 0x00de8 | B3: 滝降 | C3: =LEN(B3) | E3: =LEN(D3)
A4: 0x00ded | B4: 皇狼 | C4: =LEN(B4) | E4: =LEN(D4)
A5: 0x00df2 | B5: 蓮華 | C5: =LEN(B5) | E5: =LEN(D5)
A6: 0x00df7 | B6: 徹し | C6: =LEN(B6) | E6: =LEN(D6)
A7: 0x00dfc | B7: 通背 | C7: =LEN(B7) | E7: =LEN(D7)
A8: 0x00e01 | B8: 地摺 | C8: =LEN(B8) | E8: =LEN(D8)
A9: 0x00e06 | B9: 刃紋 | C9: =LEN(B9) | E9: =LEN(D9)
A10: 0x00e0e | B10: 笹船 | C10: =LEN(B10) | E10: =LEN(D10)
A11: 0x00e13 | B11: 閃歩 | C11: =LEN(B11) | E11: =LEN(D11)
A12: 0x00e18 | B12: 抜け | C12: =LEN(B12) | E12: =LEN(D12)
A13: 0x00e1d | B13: 青竜 | C13: =LEN(B13) | E13: =LEN(D13)
A14: 0x00e22 | B14: ＥＤ居合 | C14: =LEN(B14) | E14: =LEN(D14)

Sheet SHINOBU.SMI
A1: Offset | B1: Japanese | C1: JP_len | D1: English | E1: EN_len | F1: Comments
A2: 0x010ce | B2: バーニングスフィア | C2: =LEN(B2) | E2: =LEN(D2)
A3: 0x010e1 | B3: 火龍召 | C3: =LEN(B3) | E3: =LEN(D3)
A4: 0x010e8 | B4: 符鳥刃 | C4: =LEN(B4) | D4: Bird's Blade | E4: =LEN(D4)
A5: 0x010ef | B5: 風神召 | C5: =LEN(B5) | E5: =LEN(D5)
A6: 0x010f6 | B6: シルバーソーン | C6: =LEN(B6) | E6: =LEN(D6)
A7: 0x01105 | B7: ブルーエレメント | C7: =LEN(B7) | E7: =LEN(D7)
A8: 0x01116 | B8: ターニングプラズマ | C8: =LEN(B8) | E8: =LEN(D8)
A9: 0x01129 | B9: 雷神召 | C9: =LEN(B9) | E9: =LEN(D9)
A10: 0x01130 | B10: アースファング | C10: =LEN(B10) | E10: =LEN(D10)
A11: 0x0113f | B11: 磐舟 | C11: =LEN(B11) | E11: =LEN(D11)
A12: 0x01144 | B12: 巨神召 | C12: =LEN(B12) | E12: =LEN(D12)
A13: 0x0114b | B13: スターレイン | C13: =LEN(B13) | E13: =LEN(D13)
A14: 0x01158 | B14: ワルキューレ | C14: =LEN(B14) | E14: =LEN(D14)
A15: 0x01165 | B15: スーパーボール | C15: =LEN(B15) | E15: =LEN(D15)
A16: 0x01174 | B16: ドリームミスト | C16: =LEN(B16) | E16: =LEN(D16)
... A34: 0x012be | B34: 眠り・毒・麻痺および、魔法の影響を打ち消す | C34: =LEN(B34) | E34: =LEN(D34)

Sheet Names + Places
A1: Source | B1: Japanese | C1: English
B2: シノブ・リュード | C2: Shinobu
B3: カイエス・ナインターク | C3: Keiuss
B4: エニス | C4: Innes
B5: ゴードン | C5: Gordon
B6: ゲンハス | C6: Geinhaas
B7: グラウベン | C7: Grauben
B8: ダンカン | C8: Duncan
B9: マルダー | C9: Marder
B10: ユーバウム | C10: Jubaum
B11: リール | C11: Lilie
B12: ゼフュードル | C12: Zerfuedel
B13: ルルス | C13: Lullus
... B21: ルチア | C21: Lucia
B22: サトー | C22: Satou | D22: Sato (Japanese name?)
B23: ガルサ | C23: Grueser
A25: 02OLB | B25: 港町オールバイン | C25: Port Albein
A26: 03YSK | B26: 貴族の屋敷 | C26: Nobles' Manor
A27: 04OLD | B27: 古い本の洞窟 | C27: Cave of the Ancient Book
A28: 05SKS | B28: 関所 | C28: Border Post
A29: 06BLK | B29: 首都バルクルーサ | C29: Capital City Walkreuz
A30: 07CSL | B30: バルクルーサ城 | C30: Walkreuz Castle
A31: 08CKD | B31: バルクルーサ地下道 | C31: Walkreuz Underground
A32: 09HIK | B32: 廃坑 | C32: Abandoned Mine
A33: 10TNI | B33: 谷間の遺跡 | C33: Valley Ruins
A34: 11STG | B34: 湿原 | C34: Marshlands
A35: 12MRS | B35: 森の島 | C35: Isle of Forests
A36: 13SLP | B36: 眠り姫の洞窟 | D36: Sleeping Beauty Cave | E36: Cave of Slumbers | F36: Cave of the Sleeping Princess
A37: 14YMM | B37: 辺境への山道 | C37: Frontier Pass
A38: 15MKR | B38: マッカロックの町 | D38: City McCulloch | E38: (Scottish?)
A39: 16MKI | B39: マッカロックの遺跡 | D39: Ruins McCulloch
A40: 17DRL | B40: ドラールの村 | C40: Dorral Village
A41: 18KSK | B41: 黒い鉱石の洞窟 | D41: Black Ore Cave | E41: Black Ore Mine (?)
A42: 19IRE | B42: 入り江の村 | D42: Cove-side Village | E42: Bucht Village
A43: 20NNP | B43: 難破船の入り江 | C43: Shipwreck Cove
A44: 21KTI | B44: 湖底 | D44: Lakebed | E44: Lake-floor
A45: 22MZI | B45: 湖の遺跡 | D45: Lakebed Ruins | E45: Lake-floor Ruins
A46: 23SOH | B46: ソーホゥの村 | D46: Soho Village
A47: 24UMB | B47: 海辺の村 | C47: Seaside Village
A48: 25TOU | B48: 貴族の塔 | D48: Lord's Tower | E48: Noble's Tower
...
